Workbook
Name TABLE: 'Táblas 2.1 Instrucción 5.2.IC'!$A$5:$G$40
Name TABLE_2: 'Táblas 2.1 Instrucción 5.2.IC'!$A$46:$C$53
Name TABLE_3: 'Tabla 2.2 Instrucción 5.2.IC'!$A$4:$E$15

Sheet Datos de la cuenca
B1: Expediente | C1: nº exp.
B3: Cauce | C3: cauce
B5: Situación sección de desagüe | C5: término municipal - paraje - referencias de la sección
B12: Datos de la cuenca
C16: Longitud L (km) | D16: Cota máxima (m.s.n.m.) | E16: Cota desagüe (m.s.n.m.) | F16: Pendiente media j (m/m)
B17: Cálculo de la pendiente de escorrentía | C17: L | D17: cm | E17: cd | F17: =(D17-E17)/(C17*1000) -> #VALUE!
B19: Área cuenca asociada | C19: A (km2) | D19: A
B21: Tipo terreno | C21: (tabla 2.1 y 2.2 Instrucción 5.2.IC) | D21: Tipo

Sheet Mapa Isolíneas
B2: Mapa de isolíneas. Máximas lluvias diarias en la España peninsular
B4: Pmed - Líneas moradas
B5: Cv - Líneas rojas

Sheet Tabla 7.1 Máximas lluvias
A1: Máximas Lluvias Diarias en la España Peninsular 13
A3: PERIODO DE RETORNO EN AÑOS (T)
A4: Cv 2 5 10 25 50 100 200 500
A5: 0.30 0.935 1.194 1.377 1.625 1.823 2.022 2.251 2.541
A6: 0.31 0.932 1.198 1.385 1.640 1.854 2.068 2.296 2.602
A7: 0.32 0.929 1.202 1.400 1.671 1.884 2.098 2.342 2.663
A8: 0.33 0.927 1.209 1.415 1.686 1.915 2.144 2.388 2.724
A9: 0.34 0.924 1.213 1.423 1.717 1.930 2.174 2.434 2.785
A10: 0.35 0.921 1.217 1.438 1.732 1.961 2.220 2.480 2.831
A11: 0.36 0.919 1.225 1.446 1.747 1.991 2.251 2.525 2.892
A12: 0.37 0.917 1.232 1.461 1.778 2.022 2.281 2.571 2.953
A13: 0.38 0.914 1.240 1.469 1.793 2.052 2.327 2.617 3.014
... A31: Diarias en la España Peninsular” (1997).

Sheet Táblas 2.1 Instrucción 5.2.IC
A2: Tabla 2.1 Instrucción 5.2.IC
A3: Estimación inicial del umbral de escorrentía Po (mm)
A5: USO DE LA TIERRA | B5: PENDIENTE (%) | C5: CARACTERISTICAS HIDROLOGICAS | D5: GRUPO DE SUELO
D6: A | E6: B | F6: C | G6: D
A7: Barbecho | B7: >3 | C7: R | D7: 15 | E7: 8 | F7: 6 | G7: 4
C8: N | D8: 17 | E8: 11 | F8: 8 | G8: 6
B9: <3 | C9: R/N | D9: 20 | E9: 14 | F9: 11 | G9: 8
A10: Cultivos en hilera | B10: >3 | C10: R | D10: 23 | E10: 13 | F10: 8 | G10: 6
C11: N | D11: 25 | E11: 16 | F11: 11 | G11: 8
B12: <3 | C12: R/N | D12: 28 | E12: 19 | F12: 14 | G12: 11
A13: Cereales de invierno | B13: >3 | C13: R | D13: 29 | E13: 17 | F13: 10 | G13: 8
C14: N | D14: 32 | E14: 19 | F14: 12 | G14: 10
B15: <3 | C15: R/N | D15: 34 | E15: 21 | F15: 14 | G15: 12
A16: Rotación de cultivos pobres | B16: >3 | C16: R | D16: 26 | E16: 15 | F16: 9 | G16: 6
C17: N | D17: 28 | E17: 17 | F17: 11 | G17: 8
B18: <3 | C18: R/N | D18: 30 | E18: 19 | F18: 13 | G18: 8
A19: Rotación de cultivos densos | B19: >3 | C19: R | D19: 37 | E19: 20 | F19: 12 | G19: 9
C20: N | D20: 42 | E20: 23 | F20: 14 | G20: 11
B21: <3 | C21: R/N | D21: 47 | E21: 25 | F21: 16 | G21: 13
A22: Praderas | B22: >3 | C22: Pobre | D22: 24 | E22: 14 | F22: 8 | G22: 6
C23: Media | D23: 53 | E23: 23 | F23: 14 | G23: 9
C24: Buena | D24: * | E24: 33 | F24: 18 | G24: 13
C25: Muy buena | D25: * | E25: 41 | F25: 22 | G25: 15
B26: <3 | C26: Pobre | D26: 58 | E26: 25 | F26: 12 | G26: 7
C27: Media | D27: * | E27: 35 | F27: 17 | G27: 10
C28: Buena | D28: * | E28: * | F28: 22 | G28: 14
C29: Muy buena | D29: * | E29: * | F29: 25 | G29: 16
A30: Plantaciones regulares aprovechamiento forestal | B30: >3 | C30: Pobre | D30: 62 | E30: 26 | F30: 15 | G30: 10
C31: Media | D31: * | E31: 34 | F31: 19 | G31: 14
C32: Buena | D32: * | E32: 42 | F32: 22 | G32: 15
B33: <3 | C33: Pobre | D33: * | E33: 34 | F33: 19 | G33: 14
C34: Media | D34: * | E34: 42 | F34: 22 | G34: 15
C35: Buena | D35: * | E35: 50 | F35: 25 | G35: 16
A36: Masas forestales (bosques, monte bajo, etc.) | C36: Muy clara | D36: 40 | E36: 17 | F36: 8 | G36: 5
C37: Clara | D37: 60 | E37: 24 | F37: 14 | G37: 10
C38: Media | D38: * | E38: 34 | F38: 22 | G38: 16
C39: Espesa | D39: * | E39: 47 | F39: 31 | G39: 23
C40: Muy espesa | D40: * | E40: 65 | F40: 43 | G40: 33
A41: N: denota cultivo según las curvas de nivel.
A42: R: denota cultivo según la línea de máxima pendiente.
...

Sheet Tabla 2.2 Instrucción 5.2.IC
A1: Tabla 2.2 Instrucción 5.2.IC
A2: Clasificación de suelos a efectos del umbral de escorrentía
A4: GRUPO | B4: INFILTRACION | C4: POTENCIA | D4: TEXTURA | E4: DRENAJE
B5: (cuando están
B6: muy húmedos)
A7: A | B7: Rápida | C7: Grande | D7: Arenosa Areno-limosa | E7: Perfecto
A8: B | B8: Moderada | C8: Media a grande | D8: Franco-arenosa | E8: Bueno a moderado
D9: Franca
D10: Franco-arcillosa-arenosa
D11: Franco-limosa
A12: C | B12: Lenta | C12: Media a pequeña | D12: Franco-arcillosa Franco-arcillo | E12: Imperfecto
D13: -limosa Arcillo-arenosa
A14: D | B14: Muy lenta | C14: Pequeño (litosuelo) | D14: Arcillosa | E14: Pobre o muy pobre
C15: u horizontes de arcilla

Sheet Cálculo Hidrológico
A1: Cálculo hidrológico
A4: Tiempo de concentración
A6: Tiempo que transcurre desde que una gota en el punto más alejado de la cuenca llega hasta su desembocadura | C6: tc (horas) | D6: tc = 0,3 * ( L / j ^ (1/4) ) ^ 0,76 | E6: =0.3*('Datos de la cuenca'!C17/'Datos de la cuenca'!F17^0.25)^0.76 -> #VALUE!
A8: Precipitaciones
A10: Valor medio de la máxima precipitación diaria anual | C10: Pmed (mm/día) | D10: Mapa isolíneas | E10: Pm
A11: Coeficiente de variación | C11: Cv | D11: Mapa isolíneas | E11: Cv
A13: Periodo de retorno | C13: T (años) | E13: T = 25 | F13: T = 50 | G13: T = 100 | H13: T = 500
A14: Factor de amplificación | C14: Kt | D14: Tabla 7.1 Máximas lluvias diarias España | E14: K25 | F14: K50 | G14: K100 | H14: K500
A15: Precipitación diaria máxima para el periodo de retorno considerado | C15: Pd (mm/día) | D15: Pd = Pmed * Kt | E15: =$E$10*E14 -> #VALUE! | F15: =$E$10*F14 -> #VALUE! | G15: =$E$10*G14 -> #VALUE! | H15: =$E$10*H14 -> #VALUE!
A17: Intensidades de lluvia
C19: T (años) | E19: T = 25 | F19: T = 50 | G19: T = 100 | H19: T = 500
A20: Intensidad media diaria de precipitación para el periodo de retorno T y en un intervalo igual a 1 día | C20: Id (mm/h) | D20: Id = Pd / 24 | E20: =E15/24 -> #VALUE! | F20: =F15/24 -> #VALUE! | G20: =G15/24 -> #VALUE! | H20: =H15/24 -> #VALUE!
A22: Intensidad media diaria de precipitación para el periodo de retorno T y en un intervalo igual a 1 h | C22: I1 (mm/h)
A24: Relación intensidades horaria/diaria | C24: I1 / Id | D24: Figura 2.2 Instrucción 5.2-I.C. | E24: 10
C26: T (años) | E26: T = 25 | F26: T = 50 | G26: T = 100 | H26: T = 500
A27: Intensidad media diaria de precipitación para el periodo de retorno T y en un intervalo igual a tc | C27: It (mm/h) | D27: It = Id * ( I1/Id ) ^ ( ( 1,4 - tc ^ 0,1 ) / 0,4 ) | E27: =E20*$E$24^((1.4-$E$6^0.1)/0.4) -> #VALUE! | F27: =F20*$E$24^((1.4-$E$6^0.1)/0.4) -> #VALUE! | G27: =G20*$E$24^((1.4-$E$6^0.1)/0.4) -> #VALUE! | H27: =H20*$E$24^((1.4-$E$6^0.1)/0.4) -> #VALUE!
A29: Coeficiente de escorrentía
A31: Umbral de escorentía estimado | C31: Poo (mm/día) | D31: Tabla 2-1 5.2-I.C. | E31: Poo
A32: Coeficiente corrector | C32: Ko | D32: Figura 2.5 5.2-I.C. | E32: 2.45
A33: Umbral de escorrentía definitivo | C33: Po (mm/día) | D33: Po = Poo * Ko | E33: =E31*E32 -> #VALUE!
C35: T (años) | E35: T = 25 | F35: T = 50 | G35: T = 100 | H35: T = 500
A36: Coeficiente de escorrentía | C36: C | D36: C = (Pd/Po - 1) * (Pd/Po + 23) / (Pd/Po + 11 )^2 | E36: =(E$15/$E$33-1)*(E$15/$E$33+23)/(E$15/$E$33+11)^2 -> #VALUE! | F36: =(F$15/$E$33-1)*(F$15/$E$33+23)/(F$15/$E$33+11)^2 -> #VALUE! | G36: =(G$15/$E$33-1)*(G$15/$E$33+23)/(G$15/$E$33+11)^2 -> #VALUE! | H36: =(H$15/$E$33-1)*(H$15/$E$33+23)/(H$15/$E$33+11)^2 -> #VALUE!
A38: Caudal a desaguar
A40: Coeficiente corrector método | C40: K | D40: tomando Q en m3/seg y A en km2 | E40: 3
C42: T (años) | E42: T = 25 | F42: T = 50 | G42: T = 100 | H42: T = 500
A43: Caudal en la sección de desagüe | C43: Q (m3/seg) | D43: Q = C * A * It / K | E43: =E36*'Datos de la cuenca'!$D$19*E27/3 -> #VALUE! | F43: =F36*'Datos de la cuenca'!$D$19*F27/3 -> #VALUE! | G43: =G36*'Datos de la cuenca'!$D$19*G27/3 -> #VALUE! | H43: =H36*'Datos de la cuenca'!$D$19*H27/3 -> #VALUE!

Sheet Cálculo Hidráulico
A1: Cálculo hidráulico
A4: RÉGIMEN UNIFORME EN SECCIONES CON LÁMINA LIBRE
A6: Fórmula de Manning
A8: v = 1/n * Rh ^ 2/3 * i ^ 1/2
A10: Coeficiente de Manning
B12: Tipo Sección | C12: Material sección de desagüe | H12: n
B13: I | C13: acero | H13: 0.009
B14: II | C14: madera muy bien cepillada o canales de laboratorio | H14: 0.009
B15: III | C15: madera cepillada | H15: 0.011
B16: IV | C16: fundición nueva, hormigón muy liso | H16: 0.011
B17: V | C17: hormigón con moldes metálicos | H17: 0.013
B18: VI | C18: hormigón con moldes de madera, madera con cubrejuntas, gunitado | H18: 0.014
B19: VII | C19: hormigón deteriorado | H19: 0.018
B20: VIII | C20: albañilería (piedra y ladrillo) | H20: 0.018
B21: IX | C21: tierra | H21: 0.025
B22: X | C22: roca | H22: 0.035
B23: XI | C23: cauces naturales | H23: 0.06
B24: XII | C24: cauces naturales en crecidas | H24: 0.08
B25: XIII | C25: inundaciones en planicies con obstáculos | H25: 0.14
A27: Sección trapecial simple
A29: Datos del desagüe
B31: pendiente
B32: i (tanto por uno) | C32: tipo de sección | D32: n
B33: i | C33: tipo | D33: n
A35: Datos de la sección
B37: base solera | C37: talud margen izquierda | D37: talud margen derecha | E37: calado | F37: Sección mojada | G37: Perímetro mojado | H37: Radio Hidráulico
B38: b (m) | C38: ti (tanto por uno) | D38: td (tanto por uno) | E38: h (m) | F38: S (m2) | G38: P (m) | H38: R (m)
B39: b | C39: ti | D39: td | E39: h | F39: =B39*E39+E39^2/2*(C39+D39) -> #VALUE! | G39: =B39+E39*((1+C39^2)^0.5+(1+D39^2)^0.5) -> #VALUE! | H39: =F39/G39 -> #VALUE!
A41: Resultado de capacidad
B43: calado | C43: velocidad | D43: caudal | E43: ¿CUMPLE?
B44: h (m) | C44: v (m/seg) | D44: Q (m3/seg) | E44: T = 25 | F44: T = 50 | G44: T = 100 | H44: T = 500
B45: =E39 -> h | C45: =1/D33*H39^(2/3)*B33^0.5 -> #VALUE! | D45: =C45*F39 -> #VALUE! | E45: =IF($D$45<'Cálculo Hidrológico'!E43,"NO","SI") -> #VALUE! | F45: =IF($D$45<'Cálculo Hidrológico'!F43,"NO","SI") -> #VALUE! | G45: =IF($D$45<'Cálculo Hidrológico'!G43,"NO","SI") -> #VALUE! | H45: =IF($D$45<'Cálculo Hidrológico'!H43,"NO","SI") -> #VALUE!
A47: Sección trapecial compuesta
A49: Q = ∑ Qi
A50: S = ∑ Si
A51: P = ∑ Pi
A53: Pi | B53: Perímetro mojado contacto agua - contorno
B54: El contacto agua - agua no se contabiliza
A56: Datos del desagüe
B58: pendiente | C58: tipo de sección | D58: n
...
